<?xml version="1.0"?>
<robot name="samplebot">
  <link name="world" />
  <link name="base_link" />
  <joint name="fixed" type="fixed">
    <parent link="world" />
    <child link="base_link" />
  </joint>

  <link name="base_box">
    <collision>
      <geometry>
        <box size="0.2 0.2 0.30" />
      </geometry>
    </collision>
    <visual>
      <geometry>
        <box size="0.2 0.2 0.30" />
      </geometry>
    </visual>
    <inertial>
      <origin xyz="0 0 0" rpy="0 0 0"/>
      <mass value="10.0"/>
      <inertia ixx="0.10833" iyy="0.10833" izz="0.06666" ixy="0" ixz="0" iyz="0" />
    </inertial>
  </link>
  <joint name="base_joint" type="fixed">
    <parent link="base_link" />
    <child link="base_box" />
    <origin xyz="0 0 0.15" rpy="0 0 0" />
  </joint>

  <link name="motor1_link">
    <collision>
      <geometry>
        <cylinder radius="0.04" length="0.2" />
      </geometry>
      <material name="gray" />
    </collision>
    <visual>
      <geometry>
        <cylinder radius="0.04" length="0.2" />
      </geometry>
      <material name="gray" />
    </visual>
    <inertial>
      <origin xyz="0 0 0" rpy="0 0 0"/>
      <mass value="1.0"/>
      <inertia ixx="0.00373" iyy="0.00373" izz="0.00080" ixy="0" ixz="0" iyz="0" />
    </inertial>
  </link>
  <joint name="motor1_joint" type="fixed">
    <parent link="base_box" />
    <child link="motor1_link" />
    <origin xyz="0 0 0.19" rpy="1.57 0 0" />
    <axis xyz="0 0 1" />
  </joint>

  <link name="wheel_link">
    <collision>
      <geometry>
        <cylinder radius="0.1" length="0.04" />
      </geometry>
      <material name="gray" />
    </collision>
    <visual>
      <geometry>
        <cylinder radius="0.1" length="0.04" />
      </geometry>
      <material name="gray" />
    </visual>
    <inertial>
      <origin xyz="0 0 0" rpy="0 0 0"/>
      <mass value="0.5"/>
      <inertia ixx="0.00132" iyy="0.00132" izz="0.00250" ixy="0" ixz="0" iyz="0"/>
    </inertial>
  </link>
  <joint name="wheel_joint" type="continuous">
    <parent link="motor1_link" />
    <child link="wheel_link" />
    <origin xyz="0 0 0.15" rpy="0 0 0" />
    <axis xyz="0 0 1" />
  </joint>

  <link name="bar_link">
    <visual>
    <collision>
      <geometry>
        <cylinder radius="0.01" length="0.1" />
      </geometry>
      <material name="gray" />
    </collision>
      <geometry>
        <cylinder radius="0.01" length="0.1" />
      </geometry>
      <material name="gray" />
    </visual>
    <inertial>
      <origin xyz="0 0 0" rpy="0 0 0"/>
      <mass value="10.8"/>
      <inertia ixx="0.00069" iyy="0.00069" izz="4.e-5" ixy="0" ixz="0" iyz="0" />
    </inertial>
  </link>
  <joint name="bar_joint" type="fixed">
    <parent link="wheel_link" />
    <child link="bar_link" />
    <origin xyz="0.15 0 0" rpy="0 1.570 0" />
    <axis xyz="0 0 1" />
  </joint>

  <transmission name="trans1">
    <type>transmission_interface/SimpleTransmission</type>
    <joint name="wheel_joint">
      <hardwareInterface>hardware_interface/VelocityJointInterface</hardwareInterface>
    </joint>
    <actuator name="motor1">
      <hardwareInterface>hardwawre_interface/VelocityJointInterface</hardwareInterface>
      <mechanicalReduction>1</mechanicalReduction>
    </actuator>
  </transmission>
  
  <gazebo>
    <plugin name="gazebo_ros_control" filename="libgazebo_ros_control.so">
      <robotNamespace>/samplebot</robotNamespace>
    </plugin>
  </gazebo>
</robot>
